# 16.Python 异常处理

什么是异常？
顾名思义，异常就是程序因为某种原因无法正常工作了，比如缩进错误、缺少软件包、环境错误、连接超时等等都会引发异常。

一个健壮的程序应该把所能预知的异常都应做相应的处理，应对一些简单的异常情况，使得更好的保证程序长时间运行。即使出了问题，也可让维护者一眼看出问题所在。

## 1.捕捉异常语法

```python
try:
    expression
except [Except Type]:
    expression
```

如果在执行 try 块里的业务逻辑代码时出现异常，系统自动生成一个异常对象，该异常对象被提交给 Python 解释器，这个过程被称为引发异常。

当 Python 解释器收到异常对象时，会寻找能处理该异常对象的 except 块，如果找到合适的 except 块，则把该异常对象交给该 except 块处理，这个过程被称为捕获异常。

如果 Python 解释器找不到捕获异常的 except 块，则运行时环境终止，Python 解释器也将退出。

## 2.异常类型

Python 所有的错误都是从 BaseException 类派生的，常见的错误类型和继承关系看这里：

https://docs.python.org/3/library/exceptions.html#exception-hierarchy

内置异常的类层级结构如下：

```sh
BaseException
 ├── BaseExceptionGroup
 ├── GeneratorExit
 ├── KeyboardInterrupt
 ├── SystemExit
 └── Exception
      ├── ArithmeticError
      │    ├── FloatingPointError
      │    ├── OverflowError
      │    └── ZeroDivisionError
      ├── AssertionError
      ├── AttributeError
      ├── BufferError
      ├── EOFError
      ├── ExceptionGroup [BaseExceptionGroup]
      ├── ImportError
      │    └── ModuleNotFoundError
      ├── LookupError
      │    ├── IndexError
      │    └── KeyError
      ├── MemoryError
      ├── NameError
      │    └── UnboundLocalError
      ├── OSError
      │    ├── BlockingIOError
      │    ├── ChildProcessError
      │    ├── ConnectionError
      │    │    ├── BrokenPipeError
      │    │    ├── ConnectionAbortedError
      │    │    ├── ConnectionRefusedError
      │    │    └── ConnectionResetError
      │    ├── FileExistsError
      │    ├── FileNotFoundError
      │    ├── InterruptedError
      │    ├── IsADirectoryError
      │    ├── NotADirectoryError
      │    ├── PermissionError
      │    ├── ProcessLookupError
      │    └── TimeoutError
      ├── ReferenceError
      ├── RuntimeError
      │    ├── NotImplementedError
      │    └── RecursionError
      ├── StopAsyncIteration
      ├── StopIteration
      ├── SyntaxError
      │    └── IndentationError
      │         └── TabError
      ├── SystemError
      ├── TypeError
      ├── ValueError
      │    └── UnicodeError
      │         ├── UnicodeDecodeError
      │         ├── UnicodeEncodeError
      │         └── UnicodeTranslateError
      └── Warning
           ├── BytesWarning
           ├── DeprecationWarning
           ├── EncodingWarning
           ├── FutureWarning
           ├── ImportWarning
           ├── PendingDeprecationWarning
           ├── ResourceWarning
           ├── RuntimeWarning
           ├── SyntaxWarning
           ├── UnicodeWarning
           └── UserWarning
```

常见的异常类型：

| 异常类型            | 用途                                 |
| ------------------- | ------------------------------------ |
| SyntaxError         | 语法错误                             |
| IndentationError    | 缩进错误                             |
| TypeError           | 对象类型与要求不符合                 |
| ImportError         | 模块或包导入错误；一般路径或名称错误 |
| KeyError            | 字典里面不存在的键                   |
| NameError           | 变量不存在                           |
| IndexError          | 下标超出序列范围                     |
| IOError             | 输入/输出异常；一般是无法打开文件    |
| AttributeError      | 对象里没有属性                       |
| KeyboardInterrupt   | 键盘接受到 Ctrl+C                    |
| Exception           | 通用的异常类型；一般会捕捉所有异常   |
| UnicodeEncodeError  | 编码错误                             |
| ValueError          | 传入无效的参数                       |
| SystemError         | 一般的解释器系统错误                 |
| NotImplementedError | 尚未实现的方法                       |
| AssertionError      | 断言语句失败                         |
| StopIteration       | 迭代器没有更多的值                   |
| FloatingPointError  | 浮点计算错误                         |
| OSError             | 操作系统错误                         |

## 3.异常处理

示例 1： 打印一个没有定义的变量 ，名称错误

异常处理：

```python
#!/usr/bin/env python
# -*- coding: utf-8 -*-
try:
    print(name)
except NameError:
    print("发生名称错误时，执行的代码")
```

示例 2：字符串与整数计算，类型错误

```python
#!/usr/bin/env python
# -*- coding: utf-8 -*-
try:
    n = '2' + 2
except TypeError:
    print("发生类型错误时，执行的代码")

```

在上面示例中，我们通过指定异常类型准确的处理，但在实际开发中，往往不知道会引发什么样的异常类型，这时就可以使用 Exception 类型来捕捉所有的异常。

```python
#!/usr/bin/env python
# -*- coding: utf-8 -*-

try:
    n = '2' + 2
except Exception:
    print("发生错误执行的代码")
```

这样不管是名称错误还是类型错误都可以捕获到进行处理。
在处理异常的同时，也希望能将执行的错误信息打印出来，以便让用户检查。

可以将错误输出通过 as 关键字保存到变量中，再进行打印：

```python
#!/usr/bin/env python
# -*- coding: utf-8 -*-

try:
    print(name)
except Exception as e:
    print("错误：%s" %e)
    print("发生错误执行的代码")
```

下面以 OpenStack Nova 计算项目中一个模块的实际代码段为例。代码路径：`nova/cmd/api.py`

```python
try:
    server = service.WSGIService(api, use_ssl=should_use_ssl)
    launcher.launch_service(server, workers=server.workers or 1)
    started += 1
except exception.PasteAppNotFound as ex:
    log.warning(
         _LW("%s. ``enabled_apis`` includes bad values."
                 "Fix to remove this warning."), six.text_type(ex))
```

注：except 也可以不指定异常类型，那么会忽略所有的异常类，这样做有风险，它同样会捕捉 Ctrl+C、sys.exit 等的操作，所以使用 except Exception 更好些。

## 4.else 和 finally 语句

### 4.1 else 语句

在异常处理流程中还可以添加一个 else 块，当 try 块没有出现异常时，程序会执行 else 块。

```python
#!/usr/bin/env python
# -*- coding: utf-8 -*-
name = "hujianli"
try:
    print(name)
except Exception as e:
    print("错误：%s" %e)
    print("发生错误执行的代码")
else:
    print("没有出现异常执行的代码")
```

### 4.2 finally 语句

当 try 块不管是异常，都会执行 finally。

一般用于业务逻辑处理完后的清理工作，例如打开一个文件，不管是否操作成功，都应该关闭文件。

```python
#!/usr/bin/env python
# -*- coding: utf-8 -*-
f = open("computer.txt",encoding="utf8")
try:
    data = f.read()
except Exception as e:
    print("错误：%s" %e)
    print("发生错误执行的代码")
finally:
    f.close()
```

### 4.3 try...except...else...finally

这是一个完整的语句，当一起使用时，使异常处理更加灵活。

```python
#!/usr/bin/env python
# -*- coding: utf-8 -*-
try:
    print(name)
except Exception as e:
    print("错误：%s" %e)
    print("发生错误执行的代码")
else:
    print("没有出现异常执行的代码")
finally:
    print("最后执行的代码")
```

注：它们语句的顺序必须是 try...except...else...finally，否则语法错误！里面 else 和 finally 是可选的。

### 4.4 raise 语句

我们还可以使用 raise 语句自定义触发抛出异常。raise 语法格式如下：

```python
try:
    <正常语句体>
except<异常类型>:
    raise <自定义异常语句>
```

下面以 OpenStack Nova 项目中一个模块文件的实际代码段为例。代码路径：`nova/api/auth.py`

```python
try:
    catalog_header = req.headers.get('X_SERVICE_CATALOG')
    service_catalog = jsonutils.loads(catalog_header)
except ValueError:
   raise webob.exc.HTTPInternalServerError(
        _('Invalid service catalog json.'))
```

## 5.创建自定义异常

通过创建一个新的异常类，程序可以命名自己的异常。异常应该通过直接或间接的方式继承自 Exception 类。
需要注意的是，与标准异常相似，大多数异常的命名都以“Error”结尾。

在 try 语句体中，用户自定义异常后执行 except 语句，变量 ex 是用于创建 MyError 类的实例。

```python
#!/usr/bin/env python
class MyError(Exception):
    def __init__(self, arg):
         self.args = arg

# 在自定义一个异常类后，可以触发该异常
try:
     raise MyError("This is a exception ")
except MyError as ex:
     print(ex.args)
```

raise 唯一的参数就是要抛出的异常。这个参数必须是一个异常实例或者是一个异常类（Exception 子类）

例如：抛出一个指定的异常

```python
#!/usr/bin/env python
# -*- coding: utf-8 -*-

class NameError(Exception):
    def __init__(self, arg):
         self.args = arg

name = "hujianli"
try:
    print(name)
    raise NameError("程序猿抛出的异常")
except Exception as e:
    print("错误：%s" % e)
    print("发生错误执行的代码")
else:
    print("没有出现异常执行的代码")
finally:
    print("最后执行的代码")

```

raise 参数必须是一个异常的实例或 Exception 子类。

上面用的 Exception 子类，那么我定义一个异常的实例，需要继承 Exception 类：

```python
#!/usr/bin/env python
# -*- coding: utf-8 -*-
class MyError(Exception):
    def __init__(self, msg):
        self.msg = msg

    def __str__(self):  # __str__自动打印这个方法 return 的数据
        return self.msg


try:
    if 1 != 2:
        raise MyError("手动引发异常")
except MyError as e:
    print("自定义异常类错误: %s" % e)
```

```python
class NetworkError(Exception):
    pass

class HostnameError(NetworkError):
    pass

class TimeoutError(NetworkError):
    pass

class ProtocolError(NetworkError):
    pass
```

然后用户就可以像通常那样使用这些异常了，例如：

```sh
try:
    msg = s.recv()
except TimeoutError as e:
    # ...
except ProtocolError as e:
    # ...
```

## 6.traceback-异常和调用堆栈跟踪

https://docs.python.org/zh-cn/3.10/library/traceback.html

如果你的代码所在的环境很难获取交互 shell（比如在某个服务器上面）， 通常可以捕获异常后自己打印跟踪信息。例如：

```python
#!/usr/bin/env python
# -*- coding:utf8 -*-
# filename: 异常堆栈跟踪2.py
import traceback


class SelfException(Exception):
    pass


def main():
    firstMethod()


def firstMethod():
    SecondMethod()


def SecondMethod():
    thirdMethod()


def thirdMethod():
    raise SecondMethod("自定义异常信息")


try:
    main()
except:
    # 捕获异常信息，并将异常信息输出到控制台
    traceback.print_exc()
    # 捕获异常信息，并将异常信息输出到指定文件中
    traceback.print_exc(file=open("log.txt", "a", encoding="utf-8"))
```

```python
import traceback
try:
    10 / 0
except Exception as e:
    traceback.print_exc() # 命令行输出堆栈信息
    info = traceback.format_exc() # 保存堆栈信息到变量， 内容与上面语句一致
    print(info)
```

## 7.assert 断言

断言是指有条件地在程序代码中触发异常，如果表达式为 False，则触发异常为 AssertionError，如果没有被 try 捕获到就会终止程序。通常，断言用于测试相等性，比如在单元测试中测试某个函数执行的结果和预期值是否相等。

断言的语法格式如下：

```python
assert expression[,reason]
```

其中，assert 是断言的关键字。执行该语句时，先判断表达式 expression，如果为真，则什么都不做；如果不为真，则抛出异常。reason 则是异常类的实例。

```python
>>> assert len('openstack') == len('OpenStack')
>>> assert 5==5
>>> assert 5==6,"5 not equal 6"
Traceback (most recent call last):
   File "<pyshell#5>", line 1, in <module>
      assert 5==6,"5 not equal 6"
AssertionError: 5 not equal 6
```

我们可以看到，如果 assert 后面的表达式为真，则什么都不做；

如果不为真，就会抛出 AssertionError 异常，而且我们传进去的字符串会作为异常类的实例信息存在。

当然，assert 异常也可以被 try-except 块捕获并处理。

```python

#coding=utf-8
assert len('openstack') == len('OpenStack')
assert 5==5
assert 5==6,"5 not equal 6"

try:
    assert 5==6,"5 not equal 6"
except AssertionError,reason:
    print "%s:%s"%(reason.__class__.__name__,reason)
```

输出：

```sh
Traceback (most recent call last):
     assert 5==6,"5 not equal 6"
AssertionError: 5 not equal 6
```
